<?xml version="1.0" encoding="utf-8"?>
<!-- This URDF was automatically created by SolidWorks to URDF Exporter! Originally created by Stephen Brawner (brawner@gmail.com) 
     Commit Version: 1.6.0-1-g15f4949  Build Version: 1.6.7594.29634
     For more information, please see http://wiki.ros.org/sw_urdf_exporter -->
<robot
  name="astro_max">
  <link
    name="body_frd">
    <inertial>
      <origin
        xyz="0.00044165 0.00032802 -0.016766"
        rpy="0 0 0" />
      <mass
        value="0.88897" />
      <inertia
        ixx="0.0014518"
        ixy="-1.8944E-06"
        ixz="4.7387E-06"
        iyy="0.0018346"
        iyz="4.5747E-07"
        izz="0.0029168" />
    </inertial>
    <visual>
      <origin
        xyz="0 0 0"
        rpy="0 0 0" />
      <geometry>
        <mesh
          filename="package://astro_max/meshes/visual/body_frd.STL" />
      </geometry>
      <material
        name="">
        <color
          rgba="0 0 0 1" />
      </material>
    </visual>
    <visual>
      <origin
        xyz="0 0 0"
        rpy="0 0 0" />
      <geometry>
        <mesh
          filename="package://astro_max/meshes/visual/sl8_top_labels.STL" />
      </geometry>
      <material
        name="">
        <color
          rgba="1 1 0 1" />
      </material>
    </visual>
    <visual>
      <origin
        xyz="0 0 0"
        rpy="0 0 0" />
      <geometry>
        <mesh
          filename="package://astro_max/meshes/visual/leds_front.STL" />
      </geometry>
      <material
        name="">
        <color
          rgba="0 1 0 1" />
      </material>
    </visual>
    <visual>
      <origin
        xyz="0 0 0"
        rpy="0 0 0" />
      <geometry>
        <mesh
          filename="package://astro_max/meshes/visual/leds_back.STL" />
      </geometry>
      <material
        name="">
        <color
          rgba="1 0 0 1" />
      </material>
    </visual>
    <collision>
      <origin
        xyz="0 0 0"
        rpy="0 0 0" />
      <geometry>
        <mesh
          filename="package://astro_max/meshes/collision/body_frd.STL" />
      </geometry>
    </collision>
  </link>
  <link
    name="rotor_1_ccw">
    <inertial>
      <origin
        xyz="5.8337E-07 5.9194E-07 0.030318"
        rpy="0 0 0" />
      <mass
        value="0.097019" />
      <inertia
        ixx="0.00014275"
        ixy="-0.00012811"
        ixz="6.6887E-11"
        iyy="0.00014272"
        iyz="-3.8644E-11"
        izz="0.00028435" />
    </inertial>
    <visual>
      <origin
        xyz="0 0 0"
        rpy="0 0 0" />
      <geometry>
        <mesh
          filename="package://astro_max/meshes/visual/rotor_ccw.STL" />
      </geometry>
      <material
        name="">
        <color
          rgba="0 0 0 1" />
      </material>
    </visual>
    <visual>
      <origin
        xyz="0 0 0"
        rpy="0 0 0" />
      <geometry>
        <mesh
          filename="package://astro_max/meshes/visual/prop_bolts_ccw.STL" />
      </geometry>
      <material
        name="">
        <color
          rgba="0.75 0.75 0.75 1" />
      </material>
    </visual>
    <collision>
      <origin
        xyz="0 0 0"
        rpy="0 0 0" />
      <geometry>
        <mesh
          filename="package://astro_max/meshes/collision/rotor_ccw.STL" />
      </geometry>
    </collision>
  </link>
  <joint
    name="rotor_1_ccw_joint"
    type="continuous">
    <origin
      xyz="0.30272 0.3008 -0.067498"
      rpy="3.0984 -0.043222 0" />
    <parent
      link="body_frd" />
    <child
      link="rotor_1_ccw" />
    <axis
      xyz="0 0 1" />
  </joint>
  <link
    name="rotor_2_cw">
    <inertial>
      <origin
        xyz="-1.374E-07 -1.5473E-07 -0.02995"
        rpy="0 0 0" />
      <mass
        value="0.098646" />
      <inertia
        ixx="0.00014709"
        ixy="-0.00012804"
        ixz="6.5695E-11"
        iyy="0.00013867"
        iyz="-4.6851E-11"
        izz="0.00028439" />
    </inertial>
    <visual>
      <origin
        xyz="0 0 0"
        rpy="0 0 0" />
      <geometry>
        <mesh
          filename="package://astro_max/meshes/visual/rotor_cw.STL" />
      </geometry>
      <material
        name="">
        <color
          rgba="0 0 0 1" />
      </material>
    </visual>
    <visual>
      <origin
        xyz="0 0 0"
        rpy="0 0 0" />
      <geometry>
        <mesh
          filename="package://astro_max/meshes/visual/prop_bolts_cw.STL" />
      </geometry>
      <material
        name="">
        <color
          rgba="0.75 0.75 0.75 1" />
      </material>
    </visual>
    <collision>
      <origin
        xyz="0 0 0"
        rpy="0 0 0" />
      <geometry>
        <mesh
          filename="package://astro_max/meshes/collision/rotor_cw.STL" />
      </geometry>
    </collision>
  </link>
  <joint
    name="rotor_2_cw_joint"
    type="continuous">
    <origin
      xyz="-0.30272 0.3008 -0.067498"
      rpy="-0.043181 0.043222 0" />
    <parent
      link="body_frd" />
    <child
      link="rotor_2_cw" />
    <axis
      xyz="0 0 1" />
  </joint>
  <link
    name="rotor_3_ccw">
    <inertial>
      <origin
        xyz="-5.7558E-07 -5.8558E-07 0.02995"
        rpy="0 0 0" />
      <mass
        value="0.098645" />
      <inertia
        ixx="0.00014289"
        ixy="-0.00012811"
        ixz="-5.4517E-11"
        iyy="0.00014287"
        iyz="5.9313E-11"
        izz="0.00028439" />
    </inertial>
    <visual>
      <origin
        xyz="0 0 0"
        rpy="0 0 0" />
      <geometry>
        <mesh
          filename="package://astro_max/meshes/visual/rotor_ccw.STL" />
      </geometry>
      <material
        name="">
        <color
          rgba="0 0 0 1" />
      </material>
    </visual>
    <visual>
      <origin
        xyz="0 0 0"
        rpy="0 0 0" />
      <geometry>
        <mesh
          filename="package://astro_max/meshes/visual/prop_bolts_ccw.STL" />
      </geometry>
      <material
        name="">
        <color
          rgba="0.75 0.75 0.75 1" />
      </material>
    </visual>
    <collision>
      <origin
        xyz="0 0 0"
        rpy="0 0 0" />
      <geometry>
        <mesh
          filename="package://astro_max/meshes/collision/rotor_ccw.STL" />
      </geometry>
    </collision>
  </link>
  <joint
    name="rotor_3_ccw_axis"
    type="continuous">
    <origin
      xyz="-0.30272 -0.3008 -0.067498"
      rpy="-3.0984 0.043222 0" />
    <parent
      link="body_frd" />
    <child
      link="rotor_3_ccw" />
    <axis
      xyz="0 0 1" />
  </joint>
  <link
    name="rotor_4_cw">
    <inertial>
      <origin
        xyz="7.8271E-07 8.0848E-07 -0.02995"
        rpy="0 0 0" />
      <mass
        value="0.098646" />
      <inertia
        ixx="0.00014709"
        ixy="-0.00012804"
        ixz="-5.7774E-11"
        iyy="0.00013867"
        iyz="5.4821E-11"
        izz="0.00028439" />
    </inertial>
    <visual>
      <origin
        xyz="0 0 0"
        rpy="0 0 0" />
      <geometry>
        <mesh
          filename="package://astro_max/meshes/visual/rotor_cw.STL" />
      </geometry>
      <material
        name="">
        <color
          rgba="0 0 0 1" />
      </material>
    </visual>
    <visual>
      <origin
        xyz="0 0 0"
        rpy="0 0 0" />
      <geometry>
        <mesh
          filename="package://astro_max/meshes/visual/prop_bolts_cw.STL" />
      </geometry>
      <material
        name="">
        <color
          rgba="0.75 0.75 0.75 1" />
      </material>
    </visual>
    <collision>
      <origin
        xyz="0 0 0"
        rpy="0 0 0" />
      <geometry>
        <mesh
          filename="package://astro_max/meshes/collision/rotor_cw.STL" />
      </geometry>
    </collision>
  </link>
  <joint
    name="rotor_4_cw_joint"
    type="continuous">
    <origin
      xyz="0.30272 -0.3008 -0.067498"
      rpy="0.043181 -0.043222 0" />
    <parent
      link="body_frd" />
    <child
      link="rotor_4_cw" />
    <axis
      xyz="0 0 1" />
  </joint>
</robot>