<?xml version="1.0" encoding="utf-8"?>
<robot
  name="astro_max">
  <link
    name="body_frd">
    <inertial>
      <origin
        xyz="0 0 0"
        rpy="0 0 0" />
      <mass
        value="8.18" />
      <inertia
        ixx="1.43E-01"
        ixy="3.26E-09"
        ixz="2.33E-10"
        iyy="1.43E-01"
        iyz="9.31E-10"
        izz="2.59E-01" />
    </inertial>
    <visual>
      <origin
        xyz="0 0 0"
        rpy="0 0 0" />
      <geometry>
        <mesh
          filename="meshes/visual/body_frd.STL" />
      </geometry>
      <material
        name="">
        <color
          rgba="0.15 0.15 0.15 1" />
      </material>
    </visual>
    <visual>
      <origin
        xyz="0 0 0"
        rpy="0 0 0" />
      <geometry>
        <mesh
          filename="meshes/visual/sl8_top_labels.STL" />
      </geometry>
      <material
        name="">
        <color
          rgba="1 1 0 1" />
      </material>
    </visual>
    <visual>
      <origin
        xyz="0 0 0"
        rpy="0 0 0" />
      <geometry>
        <mesh
          filename="meshes/visual/leds_front.STL" />
      </geometry>
      <material
        name="">
        <color
          rgba="0 1 0 1" />
      </material>
    </visual>
    <visual>
      <origin
        xyz="0 0 0"
        rpy="0 0 0" />
      <geometry>
        <mesh
          filename="meshes/visual/leds_back.STL" />
      </geometry>
      <material
        name="">
        <color
          rgba="1 0 0 1" />
      </material>
    </visual>
    <collision>
      <origin
        xyz="0 0 0"
        rpy="0 0 0" />
      <geometry>
        <mesh
          filename="meshes/collision/body_frd.STL" />
      </geometry>
    </collision>
  </link>
  <link
    name="rotor_1_ccw">
    <inertial>
      <origin
        xyz="0 0 0"
        rpy="0 0 0" />
      <mass
        value="0.25" />
      <inertia
        ixx="1.52E-04"
        ixy="0"
        ixz="0"
        iyy="1.52E-04"
        iyz="0"
        izz="2.01E-04" />
    </inertial>
    <visual>
      <origin
        xyz="0 0 0"
        rpy="0 0 0" />
      <geometry>
        <mesh
          filename="meshes/visual/rotor_ccw.STL" />
      </geometry>
      <material
        name="">
        <color
          rgba="0.15 0.15 0.15 1" />
      </material>
    </visual>
    <visual>
      <origin
        xyz="0 0 0"
        rpy="0 0 0" />
      <geometry>
        <mesh
          filename="meshes/visual/prop_bolts_ccw.STL" />
      </geometry>
      <material
        name="">
        <color
          rgba="0.75 0.75 0.75 1" />
      </material>
    </visual>
    <collision>
      <origin
        xyz="0 0 0"
        rpy="0 0 0" />
      <geometry>
        <mesh
          filename="meshes/collision/rotor_ccw.STL" />
      </geometry>
    </collision>
  </link>
  <joint
    name="rotor_1_ccw_joint"
    type="continuous">
    <origin
      xyz="0.30272 0.3008 -0.067498"
      rpy="3.0984 -0.043222 0" />
    <parent
      link="body_frd" />
    <child
      link="rotor_1_ccw" />
    <axis
      xyz="0 0 1" />
  </joint>
  <link
    name="rotor_2_cw">
    <inertial>
      <origin
        xyz="0 0 0"
        rpy="0 0 0" />
      <mass
        value="0.25" />
      <inertia
        ixx="1.52E-04"
        ixy="0"
        ixz="0"
        iyy="1.52E-04"
        iyz="0"
	izz="2.01E-04" />
    </inertial>
    <visual>
      <origin
        xyz="0 0 0"
        rpy="0 0 0" />
      <geometry>
        <mesh
          filename="meshes/visual/rotor_cw.STL" />
      </geometry>
      <material
        name="">
        <color
          rgba="0.15 0.15 0.15 1" />
      </material>
    </visual>
    <visual>
      <origin
        xyz="0 0 0"
        rpy="0 0 0" />
      <geometry>
        <mesh
          filename="meshes/visual/prop_bolts_cw.STL" />
      </geometry>
      <material
        name="">
        <color
          rgba="0.75 0.75 0.75 1" />
      </material>
    </visual>
    <collision>
      <origin
        xyz="0 0 0"
        rpy="0 0 0" />
      <geometry>
        <mesh
          filename="meshes/collision/rotor_cw.STL" />
      </geometry>
    </collision>
  </link>
  <joint
    name="rotor_2_cw_joint"
    type="continuous">
    <origin
      xyz="-0.30272 0.3008 -0.067498"
      rpy="-0.043181 0.043222 0" />
    <parent
      link="body_frd" />
    <child
      link="rotor_2_cw" />
    <axis
      xyz="0 0 1" />
  </joint>
  <link
    name="rotor_3_ccw">
    <inertial>
      <origin
        xyz="0 0 0"
        rpy="0 0 0" />
      <mass
        value="0.25"/>
      <inertia
        ixx="1.52E-04"
        ixy="0"
        ixz="0"
        iyy="1.52E-04"
        iyz="0"
        izz="1.52E-04" />
    </inertial>
    <visual>
      <origin
        xyz="0 0 0"
        rpy="0 0 0" />
      <geometry>
        <mesh
          filename="meshes/visual/rotor_ccw.STL" />
      </geometry>
      <material
        name="">
        <color
          rgba="0.15 0.15 0.15 1" />
      </material>
    </visual>
    <visual>
      <origin
        xyz="0 0 0"
        rpy="0 0 0" />
      <geometry>
        <mesh
          filename="meshes/visual/prop_bolts_ccw.STL" />
      </geometry>
      <material
        name="">
        <color
          rgba="0.75 0.75 0.75 1" />
      </material>
    </visual>
    <collision>
      <origin
        xyz="0 0 0"
        rpy="0 0 0" />
      <geometry>
        <mesh
          filename="meshes/collision/rotor_ccw.STL" />
      </geometry>
    </collision>
  </link>
  <joint
    name="rotor_3_ccw_axis"
    type="continuous">
    <origin
      xyz="-0.30272 -0.3008 -0.067498"
      rpy="-3.0984 0.043222 0" />
    <parent
      link="body_frd" />
    <child
      link="rotor_3_ccw" />
    <axis
      xyz="0 0 1" />
  </joint>
  <link
    name="rotor_4_cw">
    <inertial>
      <origin
        xyz="0 0 0"
        rpy="0 0 0" />
      <mass
        value="0.25" />
      <inertia
        ixx="1.52E-04"
        ixy="0"
        ixz="0"
        iyy="1.52E-04"
        iyz="0"
        izz="1.52E-04" />
    </inertial>
    <visual>
      <origin
        xyz="0 0 0"
        rpy="0 0 0" />
      <geometry>
        <mesh
          filename="meshes/visual/rotor_cw.STL" />
      </geometry>
      <material
        name="">
        <color
          rgba="0.15 0.15 0.15 1" />
      </material>
    </visual>
    <visual>
      <origin
        xyz="0 0 0"
        rpy="0 0 0" />
      <geometry>
        <mesh
          filename="meshes/visual/prop_bolts_cw.STL" />
      </geometry>
      <material
        name="">
        <color
          rgba="0.75 0.75 0.75 1" />
      </material>
    </visual>
    <collision>
      <origin
        xyz="0 0 0"
        rpy="0 0 0" />
      <geometry>
        <mesh
          filename="meshes/collision/rotor_cw.STL" />
      </geometry>
    </collision>
  </link>
  <joint
    name="rotor_4_cw_joint"
    type="continuous">
    <origin
      xyz="0.30272 -0.3008 -0.067498"
      rpy="0.043181 -0.043222 0" />
    <parent
      link="body_frd" />
    <child
      link="rotor_4_cw" />
    <axis
      xyz="0 0 1" />
  </joint>
</robot>
